Workbook

Sheet README
A1: Valora M2.10 - Shoprite FY2024, as ORIGINALLY reported
A3: Source: shp-afs-2024-print.pdf - Annual Financial Statements 2024, 52 weeks ended 30 June 2024, 152 pages.
A4: pdf_page is pre-filled from the actual PDF: income statement p21, balance sheet p20, cash flows p23, segments p50, HEPS p90-91.
A5: These are PDF page indices, not the printed page numbers on the page (page 48 is printed on PDF page 50).
A7: WHY THIS DOCUMENT MATTERS
A8: The FY2025 report also shows FY2024 figures - but restated. This document shows what Shoprite actually said at the time.
A9: Revenue here is 246 082. In the FY2025 report, FY2024 revenue is 236 328. Both are correct.
A10: That pair is on the Bitemporal_Pair sheet and is the reason M2.10 exists.
A12: WHAT TO WATCH FOR
A13: This document is NOT structurally the same as FY2025. Nine differences are catalogued on Structural_Changes.
A14: The most consequential: note numbers shifted between years, so note references cannot be used as stable identifiers.
A15: And: total profit and total HEPS are IDENTICAL before and after restatement - only the continuing/discontinued split moved.
... A20: Open Checks - all twelve must read PASS before this becomes golden dataset.

Sheet IncomeStatement
A1: M2.10 Consolidated statement of comprehensive income - FY2024 as originally reported
A2: Source: Shoprite Holdings Ltd, Annual Financial Statements 2024 (52 weeks ended 30 June 2024), file shp-afs-2024-print.pdf. pdf_page is the PDF page index, pre-filled. VERIFY each value against that page, then set verified to Y.
A3: Four line items exist here that are GONE from the FY2025 statement: Insurance revenue, Insurance service expenses, Net monetary gain, and 'Other operating income' (renamed).
A4: row_id | B4: statement | C4: note_ref | D4: as_reported_label | E4: period | F4: basis | G4: value_as_printed | H4: scale | I4: unit | J4: currency | K4: pdf_page | L4: verified | M4: concept_suggestion | N4: notes
A5: 1 | B5: income_statement | C5: 26 | D5: Revenue | E5: FY2024 | F5: as_reported | G5: 246082 | H5: millions | I5: currency | J5: ZAR | K5: 21 | M5: revenue_total | N5: AS REPORTED. The FY2025 report restates this to 236 328
A6: 2 | B6: income_statement | C6: 26 | D6: Revenue | E6: FY2023 | F6: restated | G6: 219645 | H6: millions | I6: currency | J6: ZAR | K6: 21 | M6: revenue_total | N6: FY2023 comparative restated for the adoption of IFRS 17 Insurance Contracts (note 45) - a DIFFERENT restatement reason than FY2025's
A7: 3 | B7: income_statement | C7: 26 | D7: Sale of merchandise | E7: FY2024 | F7: as_reported | G7: 240718 | H7: millions | I7: currency | J7: ZAR | K7: 21 | M7: revenue | N7: FY2025 report restates to 232 088
A8: 4 | B8: income_statement | C8: 26 | D8: Sale of merchandise | E8: FY2023 | F8: restated | G8: 214956 | H8: millions | I8: currency | J8: ZAR | K8: 21 | M8: revenue | N8: FY2023 comparative restated for the adoption of IFRS 17 Insurance Contracts (note 45) - a DIFFERENT restatement reason than FY2025's
A9: 5 | B9: income_statement | D9: Cost of sales | E9: FY2024 | F9: as_reported | G9: -182968 | H9: millions | I9: currency | J9: ZAR | K9: 21 | M9: cost_of_sales
A10: 6 | B10: income_statement | D10: Cost of sales | E10: FY2023 | F10: restated | G10: -163250 | H10: millions | I10: currency | J10: ZAR | K10: 21 | M10: cost_of_sales | N10: FY2023 comparative restated for the adoption of IFRS 17 Insurance Contracts (note 45) - a DIFFERENT restatement reason than FY2025's
A11: 7 | B11: income_statement | D11: Gross profit | E11: FY2024 | F11: as_reported | G11: 57750 | H11: millions | I11: currency | J11: ZAR | K11: 21 | M11: gross_profit
A12: 8 | B12: income_statement | D12: Gross profit | E12: FY2023 | F12: restated | G12: 51706 | H12: millions | I12: currency | J12: ZAR | K12: 21 | M12: gross_profit | N12: FY2023 comparative restated for the adoption of IFRS 17 Insurance Contracts (note 45) - a DIFFERENT restatement reason than FY2025's
A13: 9 | B13: income_statement | C13: 26 | D13: Other operating income | E13: FY2024 | F13: as_reported | G13: 4307 | H13: millions | I13: currency | J13: ZAR | K13: 21 | M13: alternative_revenue | N13: LABEL CHANGED: renamed 'Alternative revenue' in FY2025
A14: 10 | B14: income_statement | C14: 26 | D14: Other operating income | E14: FY2023 | F14: restated | G14: 3738 | H14: millions | I14: currency | J14: ZAR | K14: 21 | M14: alternative_revenue | N14: FY2023 comparative restated for the adoption of IFRS 17 Insurance Contracts (note 45) - a DIFFERENT restatement reason than FY2025's
A15: 11 | B15: income_statement | C15: 26 | D15: Interest revenue | E15: FY2024 | F15: as_reported | G15: 759 | H15: millions | I15: currency | J15: ZAR | K15: 21 | M15: interest_revenue
A16: 12 | B16: income_statement | C16: 26 | D16: Interest revenue | E16: FY2023 | F16: restated | G16: 701 | H16: millions | I16: currency | J16: ZAR | K16: 21 | M16: interest_revenue | N16: FY2023 comparative restated for the adoption of IFRS 17 Insurance Contracts (note 45) - a DIFFERENT restatement reason than FY2025's
A17: 13 | B17: income_statement | C17: 9 | D17: Share of profit of equity accounted investments | E17: FY2024 | F17: as_reported | G17: 268 | H17: millions | I17: currency | J17: ZAR | K17: 21 | M17: equity_accounted_profit
A18: 14 | B18: income_statement | C18: 9 | D18: Share of profit of equity accounted investments | E18: FY2023 | F18: restated | G18: 251 | H18: millions | I18: currency | J18: ZAR | K18: 21 | M18: equity_accounted_profit | N18: FY2023 comparative restated for the adoption of IFRS 17 Insurance Contracts (note 45) - a DIFFERENT restatement reason than FY2025's
A19: 15 | B19: income_statement | C19: 26 | D19: Insurance revenue | E19: FY2024 | F19: as_reported | G19: 298 | H19: millions | I19: currency | J19: ZAR | K19: 21 | M19: insurance_revenue | N19: LINE DISAPPEARS in FY2025 - reclassified to discontinued operations
A20: 16 | B20: income_statement | C20: 26 | D20: Insurance revenue | E20: FY2023 | F20: restated | G20: 250 | H20: millions | I20: currency | J20: ZAR | K20: 21 | M20: insurance_revenue | N20: FY2023 comparative restated for the adoption of IFRS 17 Insurance Contracts (note 45) - a DIFFERENT restatement reason than FY2025's
A21: 17 | B21: income_statement | C21: 12 | D21: Insurance service expenses | E21: FY2024 | F21: as_reported | G21: -178 | H21: millions | I21: currency | J21: ZAR | K21: 21 | M21: insurance_service_expenses | N21: LINE DISAPPEARS in FY2025
A22: 18 | B22: income_statement | C22: 12 | D22: Insurance service expenses | E22: FY2023 | F22: restated | G22: -133 | H22: millions | I22: currency | J22: ZAR | K22: 21 | M22: insurance_service_expenses | N22: FY2023 comparative restated for the adoption of IFRS 17 Insurance Contracts (note 45) - a DIFFERENT restatement reason than FY2025's
A23: 19 | B23: income_statement | C23: 27 | D23: Depreciation and amortisation | E23: FY2024 | F23: as_reported | G23: -7264 | H23: millions | I23: currency | J23: ZAR | K23: 21 | M23: depreciation_amortisation
A24: 20 | B24: income_statement | C24: 27 | D24: Depreciation and amortisation | E24: FY2023 | F24: restated | G24: -6305 | H24: millions | I24: currency | J24: ZAR | K24: 21 | M24: depreciation_amortisation | N24: FY2023 comparative restated for the adoption of IFRS 17 Insurance Contracts (note 45) - a DIFFERENT restatement reason than FY2025's
A25: 21 | B25: income_statement | C25: 28 | D25: Employee benefits | E25: FY2024 | F25: as_reported | G25: -19242 | H25: millions | I25: currency | J25: ZAR | K25: 21 | M25: employee_benefits
A26: 22 | B26: income_statement | C26: 28 | D26: Employee benefits | E26: FY2023 | F26: restated | G26: -17027 | H26: millions | I26: currency | J26: ZAR | K26: 21 | M26: employee_benefits | N26: FY2023 comparative restated for the adoption of IFRS 17 Insurance Contracts (note 45) - a DIFFERENT restatement reason than FY2025's
A27: 23 | B27: income_statement | C27: 43.4.1 | D27: Credit impairment losses | E27: FY2024 | F27: as_reported | G27: -381 | H27: millions | I27: currency | J27: ZAR | K27: 21 | M27: credit_impairment_losses
A28: 24 | B28: income_statement | C28: 43.4.1 | D28: Credit impairment losses | E28: FY2023 | F28: restated | G28: -264 | H28: millions | I28: currency | J28: ZAR | K28: 21 | M28: credit_impairment_losses | N28: FY2023 comparative restated for the adoption of IFRS 17 Insurance Contracts (note 45) - a DIFFERENT restatement reason than FY2025's
A29: 25 | B29: income_statement | C29: 30 | D29: Other operating expenses | E29: FY2024 | F29: as_reported | G29: -23053 | H29: millions | I29: currency | J29: ZAR | K29: 21 | M29: other_operating_expenses
A30: 26 | B30: income_statement | C30: 30 | D30: Other operating expenses | E30: FY2023 | F30: restated | G30: -20998 | H30: millions | I30: currency | J30: ZAR | K30: 21 | M30: other_operating_expenses | N30: FY2023 comparative restated for the adoption of IFRS 17 Insurance Contracts (note 45) - a DIFFERENT restatement reason than FY2025's
A31: 27 | B31: income_statement | D31: Net monetary gain | E31: FY2024 | F31: as_reported | G31: 135 | H31: millions | I31: currency | J31: ZAR | K31: 21 | M31: net_monetary_gain | N31: IAS 29 hyperinflation. LINE DISAPPEARS from the face of the FY2025 statement
A32: 28 | B32: income_statement | D32: Net monetary gain | E32: FY2023 | F32: restated | G32: 0 | H32: millions | I32: currency | J32: ZAR | K32: 21 | M32: net_monetary_gain | N32: FY2023 comparative restated for the adoption of IFRS 17 Insurance Contracts (note 45) - a DIFFERENT restatement reason than FY2025's
A33: 29 | B33: income_statement | D33: Trading profit | E33: FY2024 | F33: as_reported | G33: 13399 | H33: millions | I33: currency | J33: ZAR | K33: 21 | M33: trading_profit | N33: Company-defined measure
A34: 30 | B34: income_statement | D34: Trading profit | E34: FY2023 | F34: restated | G34: 11919 | H34: millions | I34: currency | J34: ZAR | K34: 21 | M34: trading_profit | N34: FY2023 comparative restated for the adoption of IFRS 17 Insurance Contracts (note 45) - a DIFFERENT restatement reason than FY2025's
A35: 31 | B35: income_statement | D35: Exchange rate (losses)/gains | E35: FY2024 | F35: as_reported | G35: -14 | H35: millions | I35: currency | J35: ZAR | K35: 21 | M35: fx_gains_losses
A36: 32 | B36: income_statement | D36: Exchange rate (losses)/gains | E36: FY2023 | F36: restated | G36: 384 | H36: millions | I36: currency | J36: ZAR | K36: 21 | M36: fx_gains_losses | N36: FY2023 comparative restated for the adoption of IFRS 17 Insurance Contracts (note 45) - a DIFFERENT restatement reason than FY2025's
A37: 33 | B37: income_statement | D37: Profit on lease modifications and terminations | E37: FY2024 | F37: as_reported | G37: 101 | H37: millions | I37: currency | J37: ZAR | K37: 21 | M37: lease_modification_profit
A38: 34 | B38: income_statement | D38: Profit on lease modifications and terminations | E38: FY2023 | F38: restated | G38: 60 | H38: millions | I38: currency | J38: ZAR | K38: 21 | M38: lease_modification_profit | N38: FY2023 comparative restated for the adoption of IFRS 17 Insurance Contracts (note 45) - a DIFFERENT restatement reason than FY2025's
A39: 35 | B39: income_statement | C39: 31 | D39: Items of a capital nature | E39: FY2024 | F39: as_reported | G39: -330 | H39: millions | I39: currency | J39: ZAR | K39: 21 | M39: items_of_capital_nature
A40: 36 | B40: income_statement | C40: 31 | D40: Items of a capital nature | E40: FY2023 | F40: restated | G40: -16 | H40: millions | I40: currency | J40: ZAR | K40: 21 | M40: items_of_capital_nature | N40: FY2023 comparative restated for the adoption of IFRS 17 Insurance Contracts (note 45) - a DIFFERENT restatement reason than FY2025's
...

Sheet BalanceSheet
A1: M2.6/2.10 Consolidated statement of financial position - as at 30 June 2024
A2: Source: Shoprite Holdings Ltd, Annual Financial Statements 2024 (52 weeks ended 30 June 2024), file shp-afs-2024-print.pdf. pdf_page is the PDF page index, pre-filled. VERIFY each value against that page, then set verified to Y.
A3: NOTE NUMBERS DIFFER FROM FY2025: Inventories is note 17 here, note 16 in FY2025. Stated capital 18 vs 17. Note references are not stable identifiers across years.
A4: row_id | B4: statement | C4: note_ref | D4: as_reported_label | E4: period | F4: basis | G4: value_as_printed | H4: scale | I4: unit | J4: currency | K4: pdf_page | L4: verified | M4: concept_suggestion | N4: notes
A5: 1 | B5: balance_sheet | D5: Non-current assets | E5: FY2024 | F5: as_reported | G5: 62269 | H5: millions | I5: currency | J5: ZAR | K5: 20 | M5: total_non_current_assets
A6: 2 | B6: balance_sheet | D6: Non-current assets | E6: FY2023 | F6: restated | G6: 54485 | H6: millions | I6: currency | J6: ZAR | K6: 20 | M6: total_non_current_assets | N6: IFRS 17 restatement
A7: 3 | B7: balance_sheet | C7: 3 | D7: Property, plant and equipment | E7: FY2024 | F7: as_reported | G7: 19672 | H7: millions | I7: currency | J7: ZAR | K7: 20 | M7: property_plant_equipment
A8: 4 | B8: balance_sheet | C8: 3 | D8: Property, plant and equipment | E8: FY2023 | F8: restated | G8: 16601 | H8: millions | I8: currency | J8: ZAR | K8: 20 | M8: property_plant_equipment | N8: IFRS 17 restatement
A9: 5 | B9: balance_sheet | C9: 5 | D9: Investment properties | E9: FY2024 | F9: as_reported | G9: 617 | H9: millions | I9: currency | J9: ZAR | K9: 20 | M9: investment_properties
A10: 6 | B10: balance_sheet | C10: 5 | D10: Investment properties | E10: FY2023 | F10: restated | G10: 0 | H10: millions | I10: currency | J10: ZAR | K10: 20 | M10: investment_properties | N10: IFRS 17 restatement
A11: 7 | B11: balance_sheet | C11: 6 | D11: Right-of-use assets | E11: FY2024 | F11: as_reported | G11: 30469 | H11: millions | I11: currency | J11: ZAR | K11: 20 | M11: right_of_use_assets
A12: 8 | B12: balance_sheet | C12: 6 | D12: Right-of-use assets | E12: FY2023 | F12: restated | G12: 26781 | H12: millions | I12: currency | J12: ZAR | K12: 20 | M12: right_of_use_assets | N12: IFRS 17 restatement
A13: 9 | B13: balance_sheet | C13: 7 | D13: Intangible assets | E13: FY2024 | F13: as_reported | G13: 4695 | H13: millions | I13: currency | J13: ZAR | K13: 20 | M13: intangible_assets
A14: 10 | B14: balance_sheet | C14: 7 | D14: Intangible assets | E14: FY2023 | F14: restated | G14: 4225 | H14: millions | I14: currency | J14: ZAR | K14: 20 | M14: intangible_assets | N14: IFRS 17 restatement
A15: 11 | B15: balance_sheet | C15: 9 | D15: Equity accounted investments | E15: FY2024 | F15: as_reported | G15: 2478 | H15: millions | I15: currency | J15: ZAR | K15: 20 | M15: equity_accounted_investments
A16: 12 | B16: balance_sheet | C16: 9 | D16: Equity accounted investments | E16: FY2023 | F16: restated | G16: 2312 | H16: millions | I16: currency | J16: ZAR | K16: 20 | M16: equity_accounted_investments | N16: IFRS 17 restatement
A17: 13 | B17: balance_sheet | C17: 10 | D17: Convertible loans | E17: FY2024 | F17: as_reported | G17: 0 | H17: millions | I17: currency | J17: ZAR | K17: 20 | M17: convertible_loans | N17: LINE DISAPPEARS in FY2025 - note the FY2024 note numbering differs from FY2025 throughout
A18: 14 | B18: balance_sheet | C18: 10 | D18: Convertible loans | E18: FY2023 | F18: restated | G18: 22 | H18: millions | I18: currency | J18: ZAR | K18: 20 | M18: convertible_loans | N18: IFRS 17 restatement
A19: 15 | B19: balance_sheet | C19: 11 | D19: Investments at fair value through other comprehensive income | E19: FY2024 | F19: as_reported | G19: 67 | H19: millions | I19: currency | J19: ZAR | K19: 20 | M19: investments_fvoci
A20: 16 | B20: balance_sheet | C20: 11 | D20: Investments at fair value through other comprehensive income | E20: FY2023 | F20: restated | G20: 0 | H20: millions | I20: currency | J20: ZAR | K20: 20 | M20: investments_fvoci | N20: IFRS 17 restatement
A21: 17 | B21: balance_sheet | C21: 12 | D21: Investment in insurance cell captive arrangements (non-current) | E21: FY2024 | F21: as_reported | G21: 129 | H21: millions | I21: currency | J21: ZAR | K21: 20 | M21: insurance_cell_captive_non_current
A22: 18 | B22: balance_sheet | C22: 12 | D22: Investment in insurance cell captive arrangements (non-current) | E22: FY2023 | F22: restated | G22: 128 | H22: millions | I22: currency | J22: ZAR | K22: 20 | M22: insurance_cell_captive_non_current | N22: IFRS 17 restatement
A23: 19 | B23: balance_sheet | C23: 13 | D23: Government bonds and bills (non-current) | E23: FY2024 | F23: as_reported | G23: 0 | H23: millions | I23: currency | J23: ZAR | K23: 20 | M23: government_bonds_non_current
A24: 20 | B24: balance_sheet | C24: 13 | D24: Government bonds and bills (non-current) | E24: FY2023 | F24: restated | G24: 716 | H24: millions | I24: currency | J24: ZAR | K24: 20 | M24: government_bonds_non_current | N24: IFRS 17 restatement
A25: 21 | B25: balance_sheet | C25: 14 | D25: Loans receivable (non-current) | E25: FY2024 | F25: as_reported | G25: 429 | H25: millions | I25: currency | J25: ZAR | K25: 20 | M25: loans_receivable_non_current
A26: 22 | B26: balance_sheet | C26: 14 | D26: Loans receivable (non-current) | E26: FY2023 | F26: restated | G26: 647 | H26: millions | I26: currency | J26: ZAR | K26: 20 | M26: loans_receivable_non_current | N26: IFRS 17 restatement
A27: 23 | B27: balance_sheet | C27: 15 | D27: Deferred income tax assets | E27: FY2024 | F27: as_reported | G27: 3297 | H27: millions | I27: currency | J27: ZAR | K27: 20 | M27: deferred_tax_assets
A28: 24 | B28: balance_sheet | C28: 15 | D28: Deferred income tax assets | E28: FY2023 | F28: restated | G28: 2875 | H28: millions | I28: currency | J28: ZAR | K28: 20 | M28: deferred_tax_assets | N28: IFRS 17 restatement
A29: 25 | B29: balance_sheet | C29: 16 | D29: Trade and other receivables (non-current) | E29: FY2024 | F29: as_reported | G29: 416 | H29: millions | I29: currency | J29: ZAR | K29: 20 | M29: trade_receivables_non_current
A30: 26 | B30: balance_sheet | C30: 16 | D30: Trade and other receivables (non-current) | E30: FY2023 | F30: restated | G30: 178 | H30: millions | I30: currency | J30: ZAR | K30: 20 | M30: trade_receivables_non_current | N30: IFRS 17 restatement
A31: 27 | B31: balance_sheet | D31: Current assets | E31: FY2024 | F31: as_reported | G31: 50059 | H31: millions | I31: currency | J31: ZAR | K31: 20 | M31: total_current_assets_incl_hfs
A32: 28 | B32: balance_sheet | D32: Current assets | E32: FY2023 | F32: restated | G32: 47965 | H32: millions | I32: currency | J32: ZAR | K32: 20 | M32: total_current_assets_incl_hfs | N32: IFRS 17 restatement
A33: 29 | B33: balance_sheet | C33: 17 | D33: Inventories | E33: FY2024 | F33: as_reported | G33: 28366 | H33: millions | I33: currency | J33: ZAR | K33: 20 | M33: inventories
A34: 30 | B34: balance_sheet | C34: 17 | D34: Inventories | E34: FY2023 | F34: restated | G34: 25090 | H34: millions | I34: currency | J34: ZAR | K34: 20 | M34: inventories | N34: IFRS 17 restatement
A35: 31 | B35: balance_sheet | C35: 16 | D35: Trade and other receivables (current) | E35: FY2024 | F35: as_reported | G35: 6298 | H35: millions | I35: currency | J35: ZAR | K35: 20 | M35: trade_receivables_current
A36: 32 | B36: balance_sheet | C36: 16 | D36: Trade and other receivables (current) | E36: FY2023 | F36: restated | G36: 5697 | H36: millions | I36: currency | J36: ZAR | K36: 20 | M36: trade_receivables_current | N36: IFRS 17 restatement
A37: 33 | B37: balance_sheet | D37: Current income tax assets | E37: FY2024 | F37: as_reported | G37: 736 | H37: millions | I37: currency | J37: ZAR | K37: 20 | M37: current_tax_assets
A38: 34 | B38: balance_sheet | D38: Current income tax assets | E38: FY2023 | F38: restated | G38: 441 | H38: millions | I38: currency | J38: ZAR | K38: 20 | M38: current_tax_assets | N38: IFRS 17 restatement
A39: 35 | B39: balance_sheet | C39: 12 | D39: Investment in insurance cell captive arrangements (current) | E39: FY2024 | F39: as_reported | G39: 402 | H39: millions | I39: currency | J39: ZAR | K39: 20 | M39: insurance_cell_captive_current
A40: 36 | B40: balance_sheet | C40: 12 | D40: Investment in insurance cell captive arrangements (current) | E40: FY2023 | F40: restated | G40: 383 | H40: millions | I40: currency | J40: ZAR | K40: 20 | M40: insurance_cell_captive_current | N40: IFRS 17 restatement
...

Sheet CashFlow
A1: M2.7/2.10 Consolidated statement of cash flows - year ended 30 June 2024
A2: Source: Shoprite Holdings Ltd, Annual Financial Statements 2024 (52 weeks ended 30 June 2024), file shp-afs-2024-print.pdf. pdf_page is the PDF page index, pre-filled. VERIFY each value against that page, then set verified to Y.
A4: row_id | B4: statement | C4: note_ref | D4: as_reported_label | E4: period | F4: basis | G4: value_as_printed | H4: scale | I4: unit | J4: currency | K4: pdf_page | L4: verified | M4: concept_suggestion | N4: notes
A5: 1 | B5: cash_flow | D5: Cash flows from operating activities | E5: FY2024 | F5: as_reported | G5: 13841 | H5: millions | I5: currency | J5: ZAR | K5: 23 | M5: cash_from_operating_activities
A6: 2 | B6: cash_flow | D6: Cash flows from operating activities | E6: FY2023 | F6: restated | G6: 9831 | H6: millions | I6: currency | J6: ZAR | K6: 23 | M6: cash_from_operating_activities
A7: 3 | B7: cash_flow | D7: Operating profit (per cash flow) | E7: FY2024 | F7: as_reported | G7: 12828 | H7: millions | I7: currency | J7: ZAR | K7: 23 | M7: operating_profit_cf
A8: 4 | B8: cash_flow | D8: Operating profit (per cash flow) | E8: FY2023 | F8: restated | G8: 11924 | H8: millions | I8: currency | J8: ZAR | K8: 23 | M8: operating_profit_cf
A9: 5 | B9: cash_flow | D9: Less: investment income and interest revenue earned | E9: FY2024 | F9: as_reported | G9: -1009 | H9: millions | I9: currency | J9: ZAR | K9: 23 | M9: investment_income_removed
A10: 6 | B10: cash_flow | D10: Less: investment income and interest revenue earned | E10: FY2023 | F10: restated | G10: -780 | H10: millions | I10: currency | J10: ZAR | K10: 23 | M10: investment_income_removed
A11: 7 | B11: cash_flow | C11: 38.1 | D11: Non-cash items | E11: FY2024 | F11: as_reported | G11: 8557 | H11: millions | I11: currency | J11: ZAR | K11: 23 | M11: non_cash_items
A12: 8 | B12: cash_flow | C12: 38.1 | D12: Non-cash items | E12: FY2023 | F12: restated | G12: 7268 | H12: millions | I12: currency | J12: ZAR | K12: 23 | M12: non_cash_items
A13: 9 | B13: cash_flow | C13: 38.2 | D13: Changes in working capital | E13: FY2024 | F13: as_reported | G13: 3252 | H13: millions | I13: currency | J13: ZAR | K13: 23 | M13: working_capital_movement
A14: 10 | B14: cash_flow | C14: 38.2 | D14: Changes in working capital | E14: FY2023 | F14: restated | G14: -175 | H14: millions | I14: currency | J14: ZAR | K14: 23 | M14: working_capital_movement
A15: 11 | B15: cash_flow | D15: Cash generated from operations | E15: FY2024 | F15: as_reported | G15: 23628 | H15: millions | I15: currency | J15: ZAR | K15: 23 | M15: cash_generated_from_operations
A16: 12 | B16: cash_flow | D16: Cash generated from operations | E16: FY2023 | F16: restated | G16: 18237 | H16: millions | I16: currency | J16: ZAR | K16: 23 | M16: cash_generated_from_operations
A17: 13 | B17: cash_flow | D17: Interest received | E17: FY2024 | F17: as_reported | G17: 1212 | H17: millions | I17: currency | J17: ZAR | K17: 23 | M17: interest_received_cf
A18: 14 | B18: cash_flow | D18: Interest received | E18: FY2023 | F18: restated | G18: 1080 | H18: millions | I18: currency | J18: ZAR | K18: 23 | M18: interest_received_cf
A19: 15 | B19: cash_flow | D19: Interest paid | E19: FY2024 | F19: as_reported | G19: -4305 | H19: millions | I19: currency | J19: ZAR | K19: 23 | M19: interest_paid_cf
A20: 16 | B20: cash_flow | D20: Interest paid | E20: FY2023 | F20: restated | G20: -3664 | H20: millions | I20: currency | J20: ZAR | K20: 23 | M20: interest_paid_cf
A21: 17 | B21: cash_flow | D21: Dividends received | E21: FY2024 | F21: as_reported | G21: 568 | H21: millions | I21: currency | J21: ZAR | K21: 23 | M21: dividends_received_cf
A22: 18 | B22: cash_flow | D22: Dividends received | E22: FY2023 | F22: restated | G22: 262 | H22: millions | I22: currency | J22: ZAR | K22: 23 | M22: dividends_received_cf
A23: 19 | B23: cash_flow | C23: 38.3 | D23: Dividends paid | E23: FY2024 | F23: as_reported | G23: -3743 | H23: millions | I23: currency | J23: ZAR | K23: 23 | M23: dividends_paid_cf
A24: 20 | B24: cash_flow | C24: 38.3 | D24: Dividends paid | E24: FY2023 | F24: restated | G24: -3370 | H24: millions | I24: currency | J24: ZAR | K24: 23 | M24: dividends_paid_cf
A25: 21 | B25: cash_flow | C25: 38.4 | D25: Income tax paid | E25: FY2024 | F25: as_reported | G25: -3519 | H25: millions | I25: currency | J25: ZAR | K25: 23 | M25: income_tax_paid_cf
A26: 22 | B26: cash_flow | C26: 38.4 | D26: Income tax paid | E26: FY2023 | F26: restated | G26: -2714 | H26: millions | I26: currency | J26: ZAR | K26: 23 | M26: income_tax_paid_cf
A27: 23 | B27: cash_flow | D27: Cash flows utilised by investing activities | E27: FY2024 | F27: as_reported | G27: -6779 | H27: millions | I27: currency | J27: ZAR | K27: 23 | M27: cash_from_investing_activities
A28: 24 | B28: cash_flow | D28: Cash flows utilised by investing activities | E28: FY2023 | F28: restated | G28: -6229 | H28: millions | I28: currency | J28: ZAR | K28: 23 | M28: cash_from_investing_activities
A29: 25 | B29: cash_flow | D29: Investment in trademarks to expand operations | E29: FY2024 | F29: as_reported | G29: 0 | H29: millions | I29: currency | J29: ZAR | K29: 23 | M29: capex_trademarks | N29: Present in FY2024, ABSENT from FY2025 - one-off items come and go
A30: 26 | B30: cash_flow | D30: Investment in trademarks to expand operations | E30: FY2023 | F30: restated | G30: -20 | H30: millions | I30: currency | J30: ZAR | K30: 23 | M30: capex_trademarks
A31: 27 | B31: cash_flow | D31: Investment in property, plant and equipment and other intangible assets to expand operations | E31: FY2024 | F31: as_reported | G31: -5718 | H31: millions | I31: currency | J31: ZAR | K31: 23 | M31: capex_expansion
A32: 28 | B32: cash_flow | D32: Investment in property, plant and equipment and other intangible assets to expand operations | E32: FY2023 | F32: restated | G32: -4594 | H32: millions | I32: currency | J32: ZAR | K32: 23 | M32: capex_expansion
A33: 29 | B33: cash_flow | D33: Investment in property, plant and equipment and other intangible assets to maintain operations | E33: FY2024 | F33: as_reported | G33: -2012 | H33: millions | I33: currency | J33: ZAR | K33: 23 | M33: capex_maintenance
A34: 30 | B34: cash_flow | D34: Investment in property, plant and equipment and other intangible assets to maintain operations | E34: FY2023 | F34: restated | G34: -2095 | H34: millions | I34: currency | J34: ZAR | K34: 23 | M34: capex_maintenance
A35: 31 | B35: cash_flow | D35: Investment in assets classified as held for sale | E35: FY2024 | F35: as_reported | G35: -32 | H35: millions | I35: currency | J35: ZAR | K35: 23 | M35: investment_assets_held_for_sale
A36: 32 | B36: cash_flow | D36: Investment in assets classified as held for sale | E36: FY2023 | F36: restated | G36: -46 | H36: millions | I36: currency | J36: ZAR | K36: 23 | M36: investment_assets_held_for_sale
A37: 33 | B37: cash_flow | D37: Investment in convertible loans | E37: FY2024 | F37: as_reported | G37: -5 | H37: millions | I37: currency | J37: ZAR | K37: 23 | M37: investment_convertible_loans
A38: 34 | B38: cash_flow | D38: Investment in convertible loans | E38: FY2023 | F38: restated | G38: -20 | H38: millions | I38: currency | J38: ZAR | K38: 23 | M38: investment_convertible_loans
A39: 35 | B39: cash_flow | D39: Payment for investments at fair value through other comprehensive income | E39: FY2024 | F39: as_reported | G39: -4 | H39: millions | I39: currency | J39: ZAR | K39: 23 | M39: payment_investments_fvoci
A40: 36 | B40: cash_flow | D40: Payment for investments at fair value through other comprehensive income | E40: FY2023 | F40: restated | G40: 0 | H40: millions | I40: currency | J40: ZAR | K40: 23 | M40: payment_investments_fvoci
A41: 37 | B41: cash_flow | D41: Proceeds on disposal of property, plant and equipment and intangible assets | E41: FY2024 | F41: as_reported | G41: 400 | H41: millions | I41: currency | J41: ZAR | K41: 23 | M41: proceeds_disposal_ppe
...

Sheet HEPS
A1: M2.8/2.10 Headline earnings reconciliation (note 36) - FY2024 as originally reported
A2: Source: Shoprite Holdings Ltd, Annual Financial Statements 2024 (52 weeks ended 30 June 2024), file shp-afs-2024-print.pdf. pdf_page is the PDF page index, pre-filled. VERIFY each value against that page, then set verified to Y.
A4: row_id | B4: statement | C4: note_ref | D4: as_reported_label | E4: period | F4: basis | G4: value_as_printed | H4: scale | I4: unit | J4: currency | K4: pdf_page | L4: verified | M4: concept_suggestion | N4: notes
A5: 1 | B5: heps_reconciliation | C5: 36 | D5: Net profit attributable to owners of the parent [net] | E5: FY2024 | F5: as_reported | G5: 6248 | H5: millions | I5: currency | J5: ZAR | K5: 90 | M5: profit_attributable_owners_net
A6: 2 | B6: heps_reconciliation | C6: 36 | D6: Loss from discontinued operations [net] | E6: FY2024 | F6: as_reported | G6: 322 | H6: millions | I6: currency | J6: ZAR | K6: 90 | M6: heps_adj_discontinued_net
A7: 3 | B7: heps_reconciliation | C7: 36 | D7: Earnings from continuing operations [net] | E7: FY2024 | F7: as_reported | G7: 6570 | H7: millions | I7: currency | J7: ZAR | K7: 90 | M7: earnings_continuing_net
A8: 4 | B8: heps_reconciliation | C8: 36 | D8: Profit on disposal of assets classified as held for sale [gross] | E8: FY2024 | F8: as_reported | G8: -9 | H8: millions | I8: currency | J8: ZAR | K8: 90 | M8: heps_adj_disposal_held_for_sale_gross
A9: 5 | B9: heps_reconciliation | C9: 36 | D9: Profit on disposal of assets classified as held for sale [tax effect] | E9: FY2024 | F9: as_reported | G9: 0 | H9: millions | I9: currency | J9: ZAR | K9: 90 | M9: heps_adj_disposal_held_for_sale_tax
A10: 6 | B10: heps_reconciliation | C10: 36 | D10: Profit on disposal of assets classified as held for sale [net] | E10: FY2024 | F10: as_reported | G10: -9 | H10: millions | I10: currency | J10: ZAR | K10: 90 | M10: heps_adj_disposal_held_for_sale_net
A11: 7 | B11: heps_reconciliation | C11: 36 | D11: Profit on sale and leaseback transaction [gross] | E11: FY2024 | F11: as_reported | G11: -49 | H11: millions | I11: currency | J11: ZAR | K11: 90 | M11: heps_adj_sale_leaseback_gross
A12: 8 | B12: heps_reconciliation | C12: 36 | D12: Profit on sale and leaseback transaction [tax effect] | E12: FY2024 | F12: as_reported | G12: 17 | H12: millions | I12: currency | J12: ZAR | K12: 90 | M12: heps_adj_sale_leaseback_tax
A13: 9 | B13: heps_reconciliation | C13: 36 | D13: Profit on sale and leaseback transaction [net] | E13: FY2024 | F13: as_reported | G13: -32 | H13: millions | I13: currency | J13: ZAR | K13: 90 | M13: heps_adj_sale_leaseback_net
A14: 10 | B14: heps_reconciliation | C14: 36 | D14: Loss on disposal and scrapping of property, plant and equipment and intangible assets [gross] | E14: FY2024 | F14: as_reported | G14: 143 | H14: millions | I14: currency | J14: ZAR | K14: 90 | M14: heps_adj_disposal_ppe_gross
A15: 11 | B15: heps_reconciliation | C15: 36 | D15: Loss on disposal and scrapping of property, plant and equipment and intangible assets [tax effect] | E15: FY2024 | F15: as_reported | G15: -37 | H15: millions | I15: currency | J15: ZAR | K15: 90 | M15: heps_adj_disposal_ppe_tax
A16: 12 | B16: heps_reconciliation | C16: 36 | D16: Loss on disposal and scrapping of property, plant and equipment and intangible assets [net] | E16: FY2024 | F16: as_reported | G16: 106 | H16: millions | I16: currency | J16: ZAR | K16: 90 | M16: heps_adj_disposal_ppe_net
... A50: 46 | B50: heps_reconciliation | C50: 36 | D50: Headline earnings [net] | E50: FY2024 | F50: as_reported | G50: 6482 | H50: millions | I50: currency | J50: ZAR | K50: 90 | M50: headline_earnings_net
A51: 47 | B51: heps_reconciliation | C51: 36 | D51: Headline earnings per share from continuing operations (cents) | E51: FY2024 | F51: as_reported | G51: 1250.5 | H51: units | I51: cents_per_share | J51: ZAR | K51: 91 | M51: heps_continuing | N51: FY2025 report restates this to 1 185.3
A52: 48 | B52: heps_reconciliation | C52: 36 | D52: Headline earnings per share - discontinued (cents) | E52: FY2024 | F52: as_reported | G52: -59.1 | H52: units | I52: cents_per_share | J52: ZAR | K52: 91 | M52: heps_discontinued
A53: 49 | B53: heps_reconciliation | C53: 36 | D53: Headline earnings per share - total (cents) | E53: FY2024 | F53: as_reported | G53: 1191.4 | H53: units | I53: cents_per_share | J53: ZAR | K53: 91 | M53: heps_total | N53: UNCHANGED by the restatement - only the continuing/discontinued split moved
A54: 50 | B54: heps_reconciliation | C54: 36 | D54: Diluted headline earnings per share - total (cents) | E54: FY2024 | F54: as_reported | G54: 1186.3 | H54: units | I54: cents_per_share | J54: ZAR | K54: 91 | M54: heps_diluted_total

Sheet Segments
A1: M2.9/2.10 Operating segment information (note 2.1) - FY2024, FOUR reportable segments
A2: Source: Shoprite Holdings Ltd, Annual Financial Statements 2024 (52 weeks ended 30 June 2024), file shp-afs-2024-print.pdf. pdf_page is the PDF page index, pre-filled. VERIFY each value against that page, then set verified to Y.
A3: FY2024 has four segments; FY2025 has three. Furniture became a discontinued operation. Segment identity is not stable across years.
A4: row_id | B4: statement | C4: note_ref | D4: as_reported_label | E4: period | F4: basis | G4: value_as_printed | H4: scale | I4: unit | J4: currency | K4: pdf_page | L4: verified | M4: concept_suggestion | N4: notes
A5: 1 | B5: segment_note | C5: 2.1 | D5: Sale of merchandise - external :: Supermarkets RSA | E5: FY2024 | F5: as_reported | G5: 195041 | H5: millions | I5: currency | J5: ZAR | K5: 50 | M5: segment_revenue_external
A6: 2 | B6: segment_note | C6: 2.1 | D6: Sale of merchandise - external :: Supermarkets Non-RSA | E6: FY2024 | F6: as_reported | G6: 20822 | H6: millions | I6: currency | J6: ZAR | K6: 50 | M6: segment_revenue_external
A7: 3 | B7: segment_note | C7: 2.1 | D7: Sale of merchandise - external :: Furniture | E7: FY2024 | F7: as_reported | G7: 7230 | H7: millions | I7: currency | J7: ZAR | K7: 50 | M7: segment_revenue_external | N7: FOURTH SEGMENT - does not exist in FY2025, became a discontinued operation
A8: 4 | B8: segment_note | C8: 2.1 | D8: Sale of merchandise - external :: Other operating segments | E8: FY2024 | F8: as_reported | G8: 17718 | H8: millions | I8: currency | J8: ZAR | K8: 50 | M8: segment_revenue_external
A9: 5 | B9: segment_note | C9: 2.1 | D9: Sale of merchandise - external :: Total operating segments | E9: FY2024 | F9: as_reported | G9: 240811 | H9: millions | I9: currency | J9: ZAR | K9: 50 | M9: segment_revenue_external
A10: 6 | B10: segment_note | C10: 2.1 | D10: Sale of merchandise - external :: Hyperinflation effect | E10: FY2024 | F10: as_reported | G10: -93 | H10: millions | I10: currency | J10: ZAR | K10: 50 | M10: segment_revenue_external | N10: Reconciling column. Named 'Hyperinflation effect and other reconciling items' in FY2025
A11: 7 | B11: segment_note | C11: 2.1 | D11: Sale of merchandise - external :: Consolidated | E11: FY2024 | F11: as_reported | G11: 240718 | H11: millions | I11: currency | J11: ZAR | K11: 50 | M11: segment_revenue_external
A12: 8 | B12: segment_note | C12: 2.1 | D12: Sale of merchandise - inter-segment :: Supermarkets RSA | E12: FY2024 | F12: as_reported | G12: 6392 | H12: millions | I12: currency | J12: ZAR | K12: 50 | M12: segment_revenue_intersegment
A13: 9 | B13: segment_note | C13: 2.1 | D13: Sale of merchandise - inter-segment :: Supermarkets Non-RSA | E13: FY2024 | F13: as_reported | G13: 46 | H13: millions | I13: currency | J13: ZAR | K13: 50 | M13: segment_revenue_intersegment
A14: 10 | B14: segment_note | C14: 2.1 | D14: Sale of merchandise - inter-segment :: Furniture | E14: FY2024 | F14: as_reported | G14: 0 | H14: millions | I14: currency | J14: ZAR | K14: 50 | M14: segment_revenue_intersegment | N14: FOURTH SEGMENT - does not exist in FY2025, became a discontinued operation
A15: 11 | B15: segment_note | C15: 2.1 | D15: Sale of merchandise - inter-segment :: Other operating segments | E15: FY2024 | F15: as_reported | G15: 35 | H15: millions | I15: currency | J15: ZAR | K15: 50 | M15: segment_revenue_intersegment
A16: 12 | B16: segment_note | C16: 2.1 | D16: Sale of merchandise - inter-segment :: Total operating segments | E16: FY2024 | F16: as_reported | G16: 6473 | H16: millions | I16: currency | J16: ZAR | K16: 50 | M16: segment_revenue_intersegment
A17: 13 | B17: segment_note | C17: 2.1 | D17: Sale of merchandise - inter-segment :: Hyperinflation effect | E17: FY2024 | F17: as_reported | G17: 0 | H17: millions | I17: currency | J17: ZAR | K17: 50 | M17: segment_revenue_intersegment | N17: Reconciling column. Named 'Hyperinflation effect and other reconciling items' in FY2025
A18: 14 | B18: segment_note | C18: 2.1 | D18: Sale of merchandise - inter-segment :: Consolidated | E18: FY2024 | F18: as_reported | G18: 6473 | H18: millions | I18: currency | J18: ZAR | K18: 50 | M18: segment_revenue_intersegment
A19: 15 | B19: segment_note | C19: 2.1 | D19: Sale of merchandise - total :: Supermarkets RSA | E19: FY2024 | F19: as_reported | G19: 201433 | H19: millions | I19: currency | J19: ZAR | K19: 50 | M19: segment_revenue_total
A20: 16 | B20: segment_note | C20: 2.1 | D20: Sale of merchandise - total :: Supermarkets Non-RSA | E20: FY2024 | F20: as_reported | G20: 20868 | H20: millions | I20: currency | J20: ZAR | K20: 50 | M20: segment_revenue_total
A21: 17 | B21: segment_note | C21: 2.1 | D21: Sale of merchandise - total :: Furniture | E21: FY2024 | F21: as_reported | G21: 7230 | H21: millions | I21: currency | J21: ZAR | K21: 50 | M21: segment_revenue_total | N21: FOURTH SEGMENT - does not exist in FY2025, became a discontinued operation
A22: 18 | B22: segment_note | C22: 2.1 | D22: Sale of merchandise - total :: Other operating segments | E22: FY2024 | F22: as_reported | G22: 17753 | H22: millions | I22: currency | J22: ZAR | K22: 50 | M22: segment_revenue_total
A23: 19 | B23: segment_note | C23: 2.1 | D23: Sale of merchandise - total :: Total operating segments | E23: FY2024 | F23: as_reported | G23: 247284 | H23: millions | I23: currency | J23: ZAR | K23: 50 | M23: segment_revenue_total
A24: 20 | B24: segment_note | C24: 2.1 | D24: Sale of merchandise - total :: Hyperinflation effect | E24: FY2024 | F24: as_reported | G24: -93 | H24: millions | I24: currency | J24: ZAR | K24: 50 | M24: segment_revenue_total | N24: Reconciling column. Named 'Hyperinflation effect and other reconciling items' in FY2025
A25: 21 | B25: segment_note | C25: 2.1 | D25: Sale of merchandise - total :: Consolidated | E25: FY2024 | F25: as_reported | G25: 247191 | H25: millions | I25: currency | J25: ZAR | K25: 50 | M25: segment_revenue_total
A26: 22 | B26: segment_note | C26: 2.1 | D26: Trading profit :: Supermarkets RSA | E26: FY2024 | F26: as_reported | G26: 12036 | H26: millions | I26: currency | J26: ZAR | K26: 50 | M26: segment_trading_profit
A27: 23 | B27: segment_note | C27: 2.1 | D27: Trading profit :: Supermarkets Non-RSA | E27: FY2024 | F27: as_reported | G27: 631 | H27: millions | I27: currency | J27: ZAR | K27: 50 | M27: segment_trading_profit
A28: 24 | B28: segment_note | C28: 2.1 | D28: Trading profit :: Furniture | E28: FY2024 | F28: as_reported | G28: 195 | H28: millions | I28: currency | J28: ZAR | K28: 50 | M28: segment_trading_profit | N28: FOURTH SEGMENT - does not exist in FY2025, became a discontinued operation
A29: 25 | B29: segment_note | C29: 2.1 | D29: Trading profit :: Other operating segments | E29: FY2024 | F29: as_reported | G29: 506 | H29: millions | I29: currency | J29: ZAR | K29: 50 | M29: segment_trading_profit
A30: 26 | B30: segment_note | C30: 2.1 | D30: Trading profit :: Total operating segments | E30: FY2024 | F30: as_reported | G30: 13368 | H30: millions | I30: currency | J30: ZAR | K30: 50 | M30: segment_trading_profit
A31: 27 | B31: segment_note | C31: 2.1 | D31: Trading profit :: Hyperinflation effect | E31: FY2024 | F31: as_reported | G31: 31 | H31: millions | I31: currency | J31: ZAR | K31: 50 | M31: segment_trading_profit | N31: Reconciling column. Named 'Hyperinflation effect and other reconciling items' in FY2025
A32: 28 | B32: segment_note | C32: 2.1 | D32: Trading profit :: Consolidated | E32: FY2024 | F32: as_reported | G32: 13399 | H32: millions | I32: currency | J32: ZAR | K32: 50 | M32: segment_trading_profit
A33: 29 | B33: segment_note | C33: 2.1 | D33: Interest revenue included in trading profit :: Supermarkets RSA | E33: FY2024 | F33: as_reported | G33: 102 | H33: millions | I33: currency | J33: ZAR | K33: 50 | M33: segment_interest_revenue
A34: 30 | B34: segment_note | C34: 2.1 | D34: Interest revenue included in trading profit :: Supermarkets Non-RSA | E34: FY2024 | F34: as_reported | G34: 138 | H34: millions | I34: currency | J34: ZAR | K34: 50 | M34: segment_interest_revenue
A35: 31 | B35: segment_note | C35: 2.1 | D35: Interest revenue included in trading profit :: Furniture | E35: FY2024 | F35: as_reported | G35: 445 | H35: millions | I35: currency | J35: ZAR | K35: 50 | M35: segment_interest_revenue | N35: FOURTH SEGMENT - does not exist in FY2025, became a discontinued operation
A36: 32 | B36: segment_note | C36: 2.1 | D36: Interest revenue included in trading profit :: Other operating segments | E36: FY2024 | F36: as_reported | G36: 74 | H36: millions | I36: currency | J36: ZAR | K36: 50 | M36: segment_interest_revenue
A37: 33 | B37: segment_note | C37: 2.1 | D37: Interest revenue included in trading profit :: Total operating segments | E37: FY2024 | F37: as_reported | G37: 759 | H37: millions | I37: currency | J37: ZAR | K37: 50 | M37: segment_interest_revenue
A38: 34 | B38: segment_note | C38: 2.1 | D38: Interest revenue included in trading profit :: Hyperinflation effect | E38: FY2024 | F38: as_reported | G38: 0 | H38: millions | I38: currency | J38: ZAR | K38: 50 | M38: segment_interest_revenue | N38: Reconciling column. Named 'Hyperinflation effect and other reconciling items' in FY2025
A39: 35 | B39: segment_note | C39: 2.1 | D39: Interest revenue included in trading profit :: Consolidated | E39: FY2024 | F39: as_reported | G39: 759 | H39: millions | I39: currency | J39: ZAR | K39: 50 | M39: segment_interest_revenue
A40: 36 | B40: segment_note | C40: 2.1 | D40: Depreciation and amortisation :: Supermarkets RSA | E40: FY2024 | F40: as_reported | G40: 6876 | H40: millions | I40: currency | J40: ZAR | K40: 50 | M40: segment_depreciation_amortisation
...

Sheet Bitemporal_Pair
A1: THE PAIR - FY2024 as originally reported vs as restated a year later
A2: Source: Shoprite Holdings Ltd, Annual Financial Statements 2024 (52 weeks ended 30 June 2024), file shp-afs-2024-print.pdf. pdf_page is the PDF page index, pre-filled. VERIFY each value against that page, then set verified to Y.
A3: Two documents, one fiscal year, two correct answers. Note that 'Profit for the year' and total HEPS are IDENTICAL in both - the restatement reclassified between continuing and discontinued without changing the totals. A naive diff that only compares bottom-line profit would conclude nothing changed.
A4: row_id | B4: statement | C4: note_ref | D4: as_reported_label | E4: period | F4: basis | G4: value_as_printed | H4: scale | I4: unit | J4: currency | K4: pdf_page | L4: verified | M4: concept_suggestion | N4: notes
A5: 1 | B5: bitemporal_pair | D5: FY2024 Revenue | E5: FY2024 | F5: as_reported | G5: 246082 | H5: millions | I5: currency | J5: ZAR | K5: 21 | M5: revenue | N5: Believed from Sept 2024 (FY2024 AFS) until Oct 2025
A6: 2 | B6: bitemporal_pair | C6: 45 | D6: FY2024 Revenue | E6: FY2024 | F6: restated | G6: 236328 | H6: millions | I6: currency | J6: ZAR | M6: revenue | N6: Believed from Oct 2025 (FY2025 AFS note 45) onward. pdf_page refers to the FY2025 document, not this one
A7: 3 | B7: bitemporal_pair | D7: FY2024 Sale of merchandise | E7: FY2024 | F7: as_reported | G7: 240718 | H7: millions | I7: currency | J7: ZAR | K7: 21 | M7: sale_of_merchandise | N7: Believed from Sept 2024 (FY2024 AFS) until Oct 2025
A8: 4 | B8: bitemporal_pair | C8: 45 | D8: FY2024 Sale of merchandise | E8: FY2024 | F8: restated | G8: 232088 | H8: millions | I8: currency | J8: ZAR | M8: sale_of_merchandise | N8: Believed from Oct 2025 (FY2025 AFS note 45) onward. pdf_page refers to the FY2025 document, not this one
A9: 5 | B9: bitemporal_pair | D9: FY2024 Cost of sales | E9: FY2024 | F9: as_reported | G9: -182968 | H9: millions | I9: currency | J9: ZAR | K9: 21 | M9: cost_of_sales | N9: Believed from Sept 2024 (FY2024 AFS) until Oct 2025
A10: 6 | B10: bitemporal_pair | C10: 45 | D10: FY2024 Cost of sales | E10: FY2024 | F10: restated | G10: -176549 | H10: millions | I10: currency | J10: ZAR | M10: cost_of_sales | N10: Believed from Oct 2025 (FY2025 AFS note 45) onward. pdf_page refers to the FY2025 document, not this one
A11: 7 | B11: bitemporal_pair | D11: FY2024 Gross profit | E11: FY2024 | F11: as_reported | G11: 57750 | H11: millions | I11: currency | J11: ZAR | K11: 21 | M11: gross_profit | N11: Believed from Sept 2024 (FY2024 AFS) until Oct 2025
A12: 8 | B12: bitemporal_pair | C12: 45 | D12: FY2024 Gross profit | E12: FY2024 | F12: restated | G12: 55539 | H12: millions | I12: currency | J12: ZAR | M12: gross_profit | N12: Believed from Oct 2025 (FY2025 AFS note 45) onward. pdf_page refers to the FY2025 document, not this one
A13: 9 | B13: bitemporal_pair | D13: FY2024 Other operating income / Alternative revenue | E13: FY2024 | F13: as_reported | G13: 4307 | H13: millions | I13: currency | J13: ZAR | K13: 21 | M13: other_operating_income_/_alternative_revenue | N13: Believed from Sept 2024 (FY2024 AFS) until Oct 2025
A14: 10 | B14: bitemporal_pair | C14: 45 | D14: FY2024 Other operating income / Alternative revenue | E14: FY2024 | F14: restated | G14: 3927 | H14: millions | I14: currency | J14: ZAR | M14: other_operating_income_/_alternative_revenue | N14: Believed from Oct 2025 (FY2025 AFS note 45) onward. pdf_page refers to the FY2025 document, not this one
A15: 11 | B15: bitemporal_pair | D15: FY2024 Interest revenue | E15: FY2024 | F15: as_reported | G15: 759 | H15: millions | I15: currency | J15: ZAR | K15: 21 | M15: interest_revenue | N15: Believed from Sept 2024 (FY2024 AFS) until Oct 2025
A16: 12 | B16: bitemporal_pair | C16: 45 | D16: FY2024 Interest revenue | E16: FY2024 | F16: restated | G16: 313 | H16: millions | I16: currency | J16: ZAR | M16: interest_revenue | N16: Believed from Oct 2025 (FY2025 AFS note 45) onward. pdf_page refers to the FY2025 document, not this one
A17: 13 | B17: bitemporal_pair | D17: FY2024 Depreciation and amortisation | E17: FY2024 | F17: as_reported | G17: -7264 | H17: millions | I17: currency | J17: ZAR | K17: 21 | M17: depreciation_and_amortisation | N17: Believed from Sept 2024 (FY2024 AFS) until Oct 2025
A18: 14 | B18: bitemporal_pair | C18: 45 | D18: FY2024 Depreciation and amortisation | E18: FY2024 | F18: restated | G18: -6845 | H18: millions | I18: currency | J18: ZAR | M18: depreciation_and_amortisation | N18: Believed from Oct 2025 (FY2025 AFS note 45) onward. pdf_page refers to the FY2025 document, not this one
A19: 15 | B19: bitemporal_pair | D19: FY2024 Employee benefits | E19: FY2024 | F19: as_reported | G19: -19242 | H19: millions | I19: currency | J19: ZAR | K19: 21 | M19: employee_benefits | N19: Believed from Sept 2024 (FY2024 AFS) until Oct 2025
A20: 16 | B20: bitemporal_pair | C20: 45 | D20: FY2024 Employee benefits | E20: FY2024 | F20: restated | G20: -18289 | H20: millions | I20: currency | J20: ZAR | M20: employee_benefits | N20: Believed from Oct 2025 (FY2025 AFS note 45) onward. pdf_page refers to the FY2025 document, not this one
A21: 17 | B21: bitemporal_pair | D21: FY2024 Credit impairment losses | E21: FY2024 | F21: as_reported | G21: -381 | H21: millions | I21: currency | J21: ZAR | K21: 21 | M21: credit_impairment_losses | N21: Believed from Sept 2024 (FY2024 AFS) until Oct 2025
A22: 18 | B22: bitemporal_pair | C22: 45 | D22: FY2024 Credit impairment losses | E22: FY2024 | F22: restated | G22: -179 | H22: millions | I22: currency | J22: ZAR | M22: credit_impairment_losses | N22: Believed from Oct 2025 (FY2025 AFS note 45) onward. pdf_page refers to the FY2025 document, not this one
A23: 19 | B23: bitemporal_pair | D23: FY2024 Other operating expenses | E23: FY2024 | F23: as_reported | G23: -23053 | H23: millions | I23: currency | J23: ZAR | K23: 21 | M23: other_operating_expenses | N23: Believed from Sept 2024 (FY2024 AFS) until Oct 2025
A24: 20 | B24: bitemporal_pair | C24: 45 | D24: FY2024 Other operating expenses | E24: FY2024 | F24: restated | G24: -21916 | H24: millions | I24: currency | J24: ZAR | M24: other_operating_expenses | N24: Believed from Oct 2025 (FY2025 AFS note 45) onward. pdf_page refers to the FY2025 document, not this one
A25: 21 | B25: bitemporal_pair | D25: FY2024 Trading profit | E25: FY2024 | F25: as_reported | G25: 13399 | H25: millions | I25: currency | J25: ZAR | K25: 21 | M25: trading_profit | N25: Believed from Sept 2024 (FY2024 AFS) until Oct 2025
A26: 22 | B26: bitemporal_pair | C26: 45 | D26: FY2024 Trading profit | E26: FY2024 | F26: restated | G26: 12818 | H26: millions | I26: currency | J26: ZAR | M26: trading_profit | N26: Believed from Oct 2025 (FY2025 AFS note 45) onward. pdf_page refers to the FY2025 document, not this one
A27: 23 | B27: bitemporal_pair | D27: FY2024 Operating profit | E27: FY2024 | F27: as_reported | G27: 13156 | H27: millions | I27: currency | J27: ZAR | K27: 21 | M27: operating_profit | N27: Believed from Sept 2024 (FY2024 AFS) until Oct 2025
A28: 24 | B28: bitemporal_pair | C28: 45 | D28: FY2024 Operating profit | E28: FY2024 | F28: restated | G28: 12662 | H28: millions | I28: currency | J28: ZAR | M28: operating_profit | N28: Believed from Oct 2025 (FY2025 AFS note 45) onward. pdf_page refers to the FY2025 document, not this one
A29: 25 | B29: bitemporal_pair | D29: FY2024 Profit before income tax | E29: FY2024 | F29: as_reported | G29: 9379 | H29: millions | I29: currency | J29: ZAR | K29: 21 | M29: profit_before_income_tax | N29: Believed from Sept 2024 (FY2024 AFS) until Oct 2025
A30: 26 | B30: bitemporal_pair | C30: 45 | D30: FY2024 Profit before income tax | E30: FY2024 | F30: restated | G30: 9026 | H30: millions | I30: currency | J30: ZAR | M30: profit_before_income_tax | N30: Believed from Oct 2025 (FY2025 AFS note 45) onward. pdf_page refers to the FY2025 document, not this one
A31: 27 | B31: bitemporal_pair | D31: FY2024 Income tax expense | E31: FY2024 | F31: as_reported | G31: -2836 | H31: millions | I31: currency | J31: ZAR | K31: 21 | M31: income_tax_expense | N31: Believed from Sept 2024 (FY2024 AFS) until Oct 2025
A32: 28 | B32: bitemporal_pair | C32: 45 | D32: FY2024 Income tax expense | E32: FY2024 | F32: restated | G32: -2805 | H32: millions | I32: currency | J32: ZAR | M32: income_tax_expense | N32: Believed from Oct 2025 (FY2025 AFS note 45) onward. pdf_page refers to the FY2025 document, not this one
A33: 29 | B33: bitemporal_pair | D33: FY2024 Profit from continuing operations | E33: FY2024 | F33: as_reported | G33: 6543 | H33: millions | I33: currency | J33: ZAR | K33: 21 | M33: profit_from_continuing_operations | N33: Believed from Sept 2024 (FY2024 AFS) until Oct 2025
A34: 30 | B34: bitemporal_pair | C34: 45 | D34: FY2024 Profit from continuing operations | E34: FY2024 | F34: restated | G34: 6221 | H34: millions | I34: currency | J34: ZAR | M34: profit_from_continuing_operations | N34: Believed from Oct 2025 (FY2025 AFS note 45) onward. pdf_page refers to the FY2025 document, not this one
A35: 31 | B35: bitemporal_pair | D35: FY2024 Profit for the year | E35: FY2024 | F35: as_reported | G35: 6221 | H35: millions | I35: currency | J35: ZAR | K35: 21 | M35: profit_for_the_year | N35: Believed from Sept 2024 (FY2024 AFS) until Oct 2025
A36: 32 | B36: bitemporal_pair | C36: 45 | D36: FY2024 Profit for the year | E36: FY2024 | F36: restated | G36: 6221 | H36: millions | I36: currency | J36: ZAR | M36: profit_for_the_year | N36: Believed from Oct 2025 (FY2025 AFS note 45) onward. pdf_page refers to the FY2025 document, not this one
A37: 33 | B37: bitemporal_pair | D37: FY2024 Headline earnings per share - total (cents) | E37: FY2024 | F37: as_reported | G37: 1191.4 | H37: units | I37: cents_per_share | J37: ZAR | K37: 21 | M37: headline_earnings_per_share_-_total_(cents) | N37: Believed from Sept 2024 (FY2024 AFS) until Oct 2025
A38: 34 | B38: bitemporal_pair | C38: 45 | D38: FY2024 Headline earnings per share - total (cents) | E38: FY2024 | F38: restated | G38: 1191.4 | H38: units | I38: cents_per_share | J38: ZAR | M38: headline_earnings_per_share_-_total_(cents) | N38: Believed from Oct 2025 (FY2025 AFS note 45) onward. pdf_page refers to the FY2025 document, not this one
A39: 35 | B39: bitemporal_pair | D39: FY2024 Headline earnings per share - continuing (cents) | E39: FY2024 | F39: as_reported | G39: 1250.5 | H39: units | I39: cents_per_share | J39: ZAR | K39: 21 | M39: headline_earnings_per_share_-_continuing_(cents) | N39: Believed from Sept 2024 (FY2024 AFS) until Oct 2025
A40: 36 | B40: bitemporal_pair | C40: 45 | D40: FY2024 Headline earnings per share - continuing (cents) | E40: FY2024 | F40: restated | G40: 1185.3 | H40: units | I40: cents_per_share | J40: ZAR | M40: headline_earnings_per_share_-_continuing_(cents) | N40: Believed from Oct 2025 (FY2025 AFS note 45) onward. pdf_page refers to the FY2025 document, not this one

Sheet Structural_Changes
A1: # | B1: What changed between FY2024 and FY2025 reports | C1: Evidence | D1: Consequence for extraction / taxonomy
A2: 1 | B2: Line renamed | C2: 'Other operating income' (FY2024) -> 'Alternative revenue' (FY2025) | D2: Same concept, different as-reported label. This is what line_item_id exists for.
A3: 2 | B3: Lines disappeared from the face | C3: Insurance revenue, Insurance service expenses, Net monetary gain present in FY2024, absent in FY2025 | D3: An extractor expecting a stable line set will report missing facts. Absence is information, not an error.
A4: 3 | B4: Line disappeared from balance sheet | C4: Convertible loans (note 10, FY2024) not present FY2025 | D4: Same.
A5: 4 | B5: Segment count changed | C5: FY2024 has 4 segments incl. Furniture; FY2025 has 3 | D5: Segment identity is not stable. A segment can cease to exist.
A6: 5 | B6: Reconciling column renamed | C6: 'Hyperinflation effect' -> 'Hyperinflation effect and other reconciling items' | D6: M5.7's segment rule keys on this column; the label moved.
A7: 6 | B7: Note numbers shifted | C7: Inventories note 17 -> 16; Stated capital 18 -> 17; Lease liabilities 21 -> 20 | D7: Note references are NOT stable identifiers. Never key provenance on a note number.
A8: 7 | B8: Restatement reason differs by year | C8: FY2024 restated FY2023 for IFRS 17. FY2025 restated FY2024 for IFRS 5. | D8: Restatements are not one kind of event. The reason matters and should be captured.
A9: 8 | B9: Totals unchanged, splits moved | C9: Profit for the year 6 221 and total HEPS 1 191.4 identical before and after restatement | D9: A restatement-detection rule that compares only headline totals will miss this entirely.
A10: 9 | B10: New disclosure appears | C10: FY2025 adds Sixty60 sales, capex expand/maintain split unchanged, Boxer-style detail | D10: New concepts arrive over time; the taxonomy must be additive.
A11: 10 | B11: Composition of 'Revenue' itself changed | C11: FY2024 Revenue = merchandise + other operating income + interest + insurance revenue (4 components, 246 082). FY2025 Revenue = merchandise + alternative revenue + interest (3 components, 256 682). | D11: A validation rule written against one year's structure FAILS on another year of the SAME company, on a correct document. M5.5 cannot hardcode which components make up a total - it must read the structure from the statement being validated.

Sheet Checks
A1: Validation checks - FY2024 as reported
A4: # | B4: Check | C4: Expected | D4: Computed | E4: Difference | F4: Result | G4: M5 rule
A5: 1 | B5: Gross profit = merchandise less cost of sales (FY2024) | C5: ='IncomeStatement'!G11 | D5: ='IncomeStatement'!G7+'IncomeStatement'!G9 | E5: =C5-D5 | F5: =IF(ABS(E5)<0.6,"PASS","FAIL") | G5: 5.5
A6: 2 | B6: Revenue = merchandise + other operating income + interest + INSURANCE (FY2024) | C6: ='IncomeStatement'!G5 | D6: ='IncomeStatement'!G7+'IncomeStatement'!G13+'IncomeStatement'!G15+IncomeStatement!G19 | E6: =C6-D6 | F6: =IF(ABS(E6)<0.6,"PASS","FAIL") | G6: 5.5
A7: 3 | B7: Profit for year = continuing + discontinued (FY2024) | C7: ='IncomeStatement'!G55 | D7: ='IncomeStatement'!G51+'IncomeStatement'!G53 | E7: =C7-D7 | F7: =IF(ABS(E7)<0.6,"PASS","FAIL") | G7: 5.5
A8: 4 | B8: Profit = owners + NCI (FY2024) | C8: ='IncomeStatement'!G55 | D8: ='IncomeStatement'!G61+'IncomeStatement'!G63 | E8: =C8-D8 | F8: =IF(ABS(E8)<0.6,"PASS","FAIL") | G8: 5.5
A9: 5 | B9: Current assets excl HFS + HFS = current assets (FY2024) | C9: ='BalanceSheet'!G31 | D9: ='BalanceSheet'!G49+'BalanceSheet'!G51 | E9: =C9-D9 | F9: =IF(ABS(E9)<0.6,"PASS","FAIL") | G9: 5.3
A10: 6 | B10: Equity attributable to owners + NCI = total equity (FY2024) | C10: ='BalanceSheet'!G65 | D10: ='BalanceSheet'!G61+'BalanceSheet'!G63 | E10: =C10-D10 | F10: =IF(ABS(E10)<0.6,"PASS","FAIL") | G10: 5.3
A11: 7 | B11: Segments + hyperinflation = consolidated revenue (FY2024) | C11: ='Segments'!G11 | D11: ='Segments'!G9+'Segments'!G10 | E11: =C11-D11 | F11: =IF(ABS(E11)<0.6,"PASS","FAIL") | G11: 5.7
A12: 8 | B12: Four segments sum to total operating segments (FY2024) | C12: ='Segments'!G9 | D12: ='Segments'!G5+'Segments'!G6+'Segments'!G7+'Segments'!G8 | E12: =C12-D12 | F12: =IF(ABS(E12)<0.6,"PASS","FAIL") | G12: 5.7
A13: 9 | B13: Segment total assets = balance sheet total assets (FY2024) | C13: ='BalanceSheet'!G53 | D13: ='Segments'!G53 | E13: =C13-D13 | F13: =IF(ABS(E13)<0.6,"PASS","FAIL") | G13: 5.7
A14: 10 | B14: HEPS foots (FY2024) | C14: ='HEPS'!G53 | D14: ='HEPS'!G50/543866*100000 | E14: =C14-D14 | F14: =IF(ABS(E14)<0.6,"PASS","FAIL") | G14: 5.6
A15: 11 | B15: Restatement left profit for the year unchanged | C15: ='Bitemporal_Pair'!G36 | D15: ='Bitemporal_Pair'!G37 | E15: =C15-D15 | F15: =IF(ABS(E15)<0.6,"PASS","FAIL") | G15: 5.9
A16: 12 | B16: Restatement left total HEPS unchanged | C16: ='Bitemporal_Pair'!G38 | D16: ='Bitemporal_Pair'!G39 | E16: =C16-D16 | F16: =IF(ABS(E16)<0.6,"PASS","FAIL") | G16: 5.9
